// SINCRONA

function dividirNumeros(num1, num2) {
  if (num2 == 0) throw new Error("N達o pode ser feito uma divis達o por zero");

  return num1 / num2;
}

try {
  const resultado = dividirNumeros(2, 1);
  console.log("resultado: %s", resultado);
} catch (e) {
  console.log(e.message);
}

// ASSINCRONA

function dividirNumeros(num1, num2) {
  const promise = new Promise((resolve, reject) => {
    if (num2 == 0) reject(Error("N達o pode ser feito uma divis達o por zero"));

    const resultado = num1 / num2;
    resolve(resultado)
  });

  return promise;
}

dividirNumeros(2, 1)
  .then(result => console.log("sucesso: %s", result))
  .catch(err => console.log("erro: %s", err.message));



// EXEMPLO 2 ___________________________________________



const fs = require('fs');

function readFilePromise (fileName) {
  return new Promise((resolve, reject) => {

    fs.readFile(fileName, (err, content) => {
      if (err) return reject(err);
      resolve(content);
    });

  });
}